Workbook

Sheet 1_Original_Dataset
A1: Original Dataset — 320 rows x 14 columns (values only — source of truth)
A2: store_id | B2: month | C2: region | D2: store_type | E2: marketing_spend | F2: footfall | G2: avg_discount_pct | H2: staff_count | I2: inventory_availability_pct | J2: competitor_distance_km | K2: holiday_flag | L2: customer_rating | M2: monthly_sales | N2: monthly_profit
A3: STR-1001 | B3: 45658 | C3: East | D3: Residential | E3: 70389.11 | F3: 8302 | G3: 0.042 | H3: 17 | I3: 75 | J3: 5.28 | K3: 1 | L3: 3.1 | M3: 658832.62 | N3: 84349.93
A4: STR-1001 | B4: 45689 | C4: East | D4: Residential | E4: 43827.89 | F4: 8487 | G4: 0.168 | H4: 23 | I4: 84.4 | J4: 4.31 | K4: 0 | L4: 2.8 | M4: 634436 | N4: 106130.54
A5: STR-1001 | B5: 45717 | C5: East | D5: Residential | E5: 59921.75 | F5: 9113 | G5: 0.133 | H5: 20 | I5: 88 | J5: 12 | K5: 0 | L5: 3.2 | M5: 678722.06 | N5: 101883.86
A6: STR-1001 | B6: 45748 | C6: East | D6: Residential | E6: 56856.63 | F6: 9431 | G6: 0.142 | H6: 23 | I6: 86.9 | J6: 4.97 | K6: 0 | L6: 3.4 | M6: 658920.3 | N6: 97910.37
A7: STR-1002 | B7: 45658 | C7: East | D7: High Street | E7: 48412.64 | F7: 9545 | G7: 0.231 | H7: 21 | I7: 97.6 | J7: 6.94 | K7: 1 | L7: 4.2 | M7: 741341.44 | N7: 119208.17
A8: STR-1002 | B8: 45689 | C8: East | D8: High Street | E8: 64811.21 | F8: 9792 | G8: 0.112 | H8: 20 | I8: 84.2 | J8: 2.88 | K8: 0 | L8: 4.2 | M8: 761835.34 | N8: 149602.23
A9: STR-1002 | B9: 45717 | C9: East | D9: High Street | E9: 46213.45 | F9: 10616 | G9: 0.122 | H9: 22 | I9: 85.2 | J9: 0.2 | K9: 1 | L9: 4.1 | M9: 806615.54 | N9: 131364.62
A10: STR-1002 | B10: 45748 | C10: East | D10: High Street | E10: 68148.52 | F10: 8567 | G10: 0.127 | H10: 23 | I10: 95.6 | J10: 0.8 | K10: 0 | L10: 3.9 | M10: 850164.26 | N10: 149262.75
A11: STR-1003 | B11: 45658 | C11: North | D11: Airport | E11: 71838.86 | F11: 10979 | G11: 0.215 | H11: 26 | I11: 88.6 | J11: 7.7 | K11: 1 | L11: 3.8 | M11: 930581.7 | N11: 136207.98
A12: STR-1003 | B12: 45689 | C12: North | D12: Airport | E12: 68133.44 | F12: 9459 | G12: 0.22 | H12: 21 | I12: 85 | J12: 1.91 | K12: 0 | L12: 4.2 | M12: 779010.94 | N12: 106328.09
A13: STR-1003 | B13: 45717 | C13: North | D13: Airport | E13: 34285.21 | F13: 9172 | G13: 0.213 | H13: 22 | I13: 88.3 | J13: 10.46 | K13: 1 | L13: 3.8 | M13: 723060.76 | N13: 123131.24
A14: STR-1003 | B14: 45748 | C14: North | D14: Airport | E14: 67979.88 | F14: 11230 | G14: 0.002 | H14: 28 | I14: 85.3 | J14: 7.16 | K14: 0 | L14: 3.8 | M14: 910791.94 | N14: 158891.28
... A35: STR-1009 | B35: 45658 | C35: North | D35: Residential | E35: 54597.83 | F35: 9429 | G35: 0.188 | H35: 21 | I35: 83.3 | J35: 11.71 | K35: 0 | L35: 4.2 | M35: 641865.03 | N35: 81342.58
A36: STR-1009 | B36: 45689 | C36: North | D36: Residential | E36: 73771.91 | F36: 11695 | G36: 0.07 | H36: 25 | I36: 84.7 | J36: 0.62 | K36: 0 | M36: 799477.76 | N36: 164974.41
A37: STR-1009 | B37: 45717 | C37: North | D37: Residential | E37: 74413.88 | F37: 9449 | G37: 0.039 | H37: 23 | I37: 92.1 | J37: 2.12 | K37: 0 | L37: 3.5 | M37: 798952.17 | N37: 161499.04
A38: STR-1009 | B38: 45748 | C38: North | D38: Residential | E38: 52483.77 | F38: 10453 | G38: 0.247 | H38: 25 | I38: 99 | J38: 6.31 | K38: 0 | L38: 3.6 | M38: 800979.78 | N38: 149242.27
A39: STR-1010 | B39: 45658 | C39: North | D39: Mall | E39: 75269.87 | F39: 8838 | G39: 0.092 | H39: 21 | I39: 83.1 | J39: 9.56 | K39: 1 | L39: 4.2 | M39: 820593.93 | N39: 115860.06
A40: STR-1010 | B40: 45689 | C40: North | D40: Mall | E40: 61245.41 | F40: 8156 | G40: 0.156 | H40: 19 | I40: 92.9 | J40: 9.05 | K40: 0 | L40: 3.8 | M40: 718330.53 | N40: 93247.9
A41: STR-1010 | B41: 45717 | C41: North | D41: Mall | E41: 93381.26 | F41: 7562 | G41: 0.198 | H41: 19 | I41: 82.9 | J41: 5.05 | K41: 0 | L41: 4 | M41: 736633.4 | N41: 115654.66
A42: STR-1010 | B42: 45748 | C42: North | D42: Mall | E42: 65012.19 | F42: 9598 | G42: 0.085 | H42: 24 | I42: 98.3 | J42: 0.89 | K42: 0 | L42: 3.8 | M42: 828623.85 | N42: 167320.52
A43: STR-1011 | B43: 45658 | C43: East | D43: Mall | E43: 40462.94 | F43: 3660 | G43: 0.218 | H43: 11 | I43: 95.2 | J43: 5.57 | K43: 0 | L43: 4.4 | M43: 592195.85 | N43: 92291.56
A44: STR-1011 | B44: 45689 | C44: East | D44: Mall | E44: 46123.88 | F44: 3227 | G44: 0.143 | H44: 10 | I44: 75.4 | J44: 1.06 | K44: 0 | L44: 4.4 | M44: 532644.46 | N44: 60681.32
A45: STR-1011 | B45: 45717 | C45: East | D45: Mall | E45: 68077.54 | F45: 3360 | G45: 0.128 | H45: 14 | I45: 88.2 | J45: 1.24 | K45: 1 | L45: 4 | M45: 657429.18 | N45: 88919.74
A46: STR-1011 | B46: 45748 | C46: East | D46: Mall | E46: 64882.14 | F46: 3642 | G46: 0.019 | H46: 13 | I46: 87.8 | J46: 4.52 | K46: 0 | L46: 4.2 | M46: 605178 | N46: 106958.74
A47: STR-1012 | B47: 45658 | C47: West | D47: Residential | E47: 138855.51 | F47: 5145 | G47: 0.06 | H47: 17 | I47: 88.2 | J47: 9.58 | K47: 0 | L47: 3.2 | M47: 595467.6 | N47: 104276.46
A48: STR-1012 | B48: 45689 | C48: West | D48: Residential | E48: 63630.21 | F48: 4460 | G48: 0.235 | H48: 14 | I48: 98.6 | J48: 5.52 | K48: 0 | L48: 3.5 | M48: 599603.4 | N48: 112685.12
... A73: STR-1018 | B73: 45717 | C73: East | D73: High Street | E73: 60571.82 | F73: 3193 | G73: 0.197 | H73: 7 | I73: 99 | J73: 1.43 | K73: 0 | L73: 3.2 | M73: 605023.87 | N73: 98545.81
A74: STR-1018 | B74: 45748 | C74: East | D74: High Street | E74: 55081.16 | F74: 5485 | G74: 0.036 | H74: 12 | I74: 88 | K74: 0 | L74: 3.5 | M74: 674774.09 | N74: 141917.59
A75: STR-1019 | B75: 45658 | C75: East | D75: Residential | E75: 46201.46 | F75: 5918 | G75: 0.277 | H75: 13 | I75: 78.8 | J75: 4.91 | K75: 0 | L75: 4.5 | M75: 616069.41 | N75: 54453.99
A76: STR-1019 | B76: 45689 | C76: East | D76: Residential | E76: 53762.92 | F76: 6821 | G76: 0.066 | H76: 19 | I76: 94.6 | J76: 7.03 | K76: 0 | L76: 4.4 | M76: 630829.94 | N76: 117090.02
A77: STR-1019 | B77: 45717 | C77: East | D77: Residential | E77: 70144.78 | F77: 6806 | G77: 0.178 | H77: 20 | I77: 93.1 | J77: 0.28 | K77: 1 | L77: 4.3 | M77: 788087.68 | N77: 116803.42
A78: STR-1019 | B78: 45748 | C78: East | D78: Residential | E78: 58749.63 | F78: 8252 | G78: 0.203 | H78: 20 | I78: 85.2 | J78: 3.61 | K78: 0 | L78: 4.5 | M78: 680840.36 | N78: 68007.68
A79: STR-1020 | B79: 45658 | C79: South | D79: High Street | E79: 56973.18 | F79: 6662 | G79: 0.1 | H79: 15 | I79: 77.7 | J79: 7.52 | K79: 1 | L79: 3.2 | M79: 643657.47 | N79: 87022.45
A80: STR-1020 | B80: 45689 | C80: South | D80: High Street | E80: 54872.82 | F80: 5962 | G80: 0.064 | H80: 12 | I80: 85.4 | J80: 2.58 | K80: 0 | L80: 2.9 | M80: 691112.6 | N80: 109212.83
A81: STR-1020 | B81: 45717 | C81: South | D81: High Street | E81: 80562.81 | F81: 7470 | G81: 0.172 | H81: 16 | I81: 83.5 | J81: 2.29 | K81: 0 | L81: 3.3 | M81: 776922.17 | N81: 150701.93
A82: STR-1020 | B82: 45748 | C82: South | D82: High Street | E82: 77999.9 | F82: 5974 | G82: 0.252 | H82: 14 | I82: 81.3 | J82: 2.39 | K82: 0 | L82: 3.2 | M82: 636561.34 | N82: 93861.06
A83: STR-1021 | B83: 45658 | C83: West | D83: Mall | E83: 60881.01 | F83: 5410 | G83: 0.179 | H83: 15 | I83: 83.9 | J83: 5.24 | K83: 0 | L83: 4.6 | M83: 621369.58 | N83: 85493.64
A84: STR-1021 | B84: 45689 | C84: West | D84: Mall | E84: 60628.38 | F84: 4451 | G84: 0.095 | H84: 10 | I84: 89.6 | J84: 3.17 | K84: 0 | L84: 4.6 | M84: 682208.01 | N84: 110318.84
...

Sheet 2_Cleaned_Data
A1: Cleaned Dataset — 306 rows (removed 14 rows with missing values). Values only; formulas operate on this sheet.
A2: store_id | B2: month | C2: region | D2: store_type | E2: marketing_spend | F2: footfall | G2: avg_discount_pct | H2: staff_count | I2: inventory_availability_pct | J2: competitor_distance_km | K2: holiday_flag | L2: customer_rating | M2: monthly_sales | N2: monthly_profit
A3: STR-1001 | B3: 45658 | C3: East | D3: Residential | E3: 70389.11 | F3: 8302 | G3: 0.042 | H3: 17 | I3: 75 | J3: 5.28 | K3: 1 | L3: 3.1 | M3: 658832.62 | N3: 84349.93
A4: STR-1001 | B4: 45689 | C4: East | D4: Residential | E4: 43827.89 | F4: 8487 | G4: 0.168 | H4: 23 | I4: 84.4 | J4: 4.31 | K4: 0 | L4: 2.8 | M4: 634436 | N4: 106130.54
A5: STR-1001 | B5: 45717 | C5: East | D5: Residential | E5: 59921.75 | F5: 9113 | G5: 0.133 | H5: 20 | I5: 88 | J5: 12 | K5: 0 | L5: 3.2 | M5: 678722.06 | N5: 101883.86
A6: STR-1001 | B6: 45748 | C6: East | D6: Residential | E6: 56856.63 | F6: 9431 | G6: 0.142 | H6: 23 | I6: 86.9 | J6: 4.97 | K6: 0 | L6: 3.4 | M6: 658920.3 | N6: 97910.37
A7: STR-1002 | B7: 45658 | C7: East | D7: High Street | E7: 48412.64 | F7: 9545 | G7: 0.231 | H7: 21 | I7: 97.6 | J7: 6.94 | K7: 1 | L7: 4.2 | M7: 741341.44 | N7: 119208.17
A8: STR-1002 | B8: 45689 | C8: East | D8: High Street | E8: 64811.21 | F8: 9792 | G8: 0.112 | H8: 20 | I8: 84.2 | J8: 2.88 | K8: 0 | L8: 4.2 | M8: 761835.34 | N8: 149602.23
A9: STR-1002 | B9: 45717 | C9: East | D9: High Street | E9: 46213.45 | F9: 10616 | G9: 0.122 | H9: 22 | I9: 85.2 | J9: 0.2 | K9: 1 | L9: 4.1 | M9: 806615.54 | N9: 131364.62
A10: STR-1002 | B10: 45748 | C10: East | D10: High Street | E10: 68148.52 | F10: 8567 | G10: 0.127 | H10: 23 | I10: 95.6 | J10: 0.8 | K10: 0 | L10: 3.9 | M10: 850164.26 | N10: 149262.75
A11: STR-1003 | B11: 45658 | C11: North | D11: Airport | E11: 71838.86 | F11: 10979 | G11: 0.215 | H11: 26 | I11: 88.6 | J11: 7.7 | K11: 1 | L11: 3.8 | M11: 930581.7 | N11: 136207.98
A12: STR-1003 | B12: 45689 | C12: North | D12: Airport | E12: 68133.44 | F12: 9459 | G12: 0.22 | H12: 21 | I12: 85 | J12: 1.91 | K12: 0 | L12: 4.2 | M12: 779010.94 | N12: 106328.09
A13: STR-1003 | B13: 45717 | C13: North | D13: Airport | E13: 34285.21 | F13: 9172 | G13: 0.213 | H13: 22 | I13: 88.3 | J13: 10.46 | K13: 1 | L13: 3.8 | M13: 723060.76 | N13: 123131.24
A14: STR-1003 | B14: 45748 | C14: North | D14: Airport | E14: 67979.88 | F14: 11230 | G14: 0.002 | H14: 28 | I14: 85.3 | J14: 7.16 | K14: 0 | L14: 3.8 | M14: 910791.94 | N14: 158891.28
... A308: STR-1080 | B308: 45748 | C308: East | D308: Residential | E308: 40553.11 | F308: 5317 | G308: 0.165 | H308: 17 | I308: 84.3 | J308: 11.82 | K308: 0 | L308: 4.1 | M308: 559660.84 | N308: 71443.61

Sheet 3_Dummy_Variables
A1: Dummy Variables for store_type — IF formulas from '2_Cleaned_Data'. Reference category: Residential (dropped).
A2: Dummy formula example — Column D row 5: =IF('2_Cleaned_Data'!D3="Airport",1,0)
A3: store_id | B3: month | C3: store_type | D3: store_Airport | E3: store_HighStreet | F3: store_Mall
A4: ='2_Cleaned_Data'!A3 -> STR-1001 | B4: ='2_Cleaned_Data'!B3 -> 45658 | C4: ='2_Cleaned_Data'!D3 -> Residential | D4: =IF('2_Cleaned_Data'!D3="Airport",1,0) -> 0 | E4: =IF('2_Cleaned_Data'!D3="High Street",1,0) -> 0 | F4: =IF('2_Cleaned_Data'!D3="Mall",1,0) -> 0
A5: ='2_Cleaned_Data'!A4 -> STR-1001 | B5: ='2_Cleaned_Data'!B4 -> 45689 | C5: ='2_Cleaned_Data'!D4 -> Residential | D5: =IF('2_Cleaned_Data'!D4="Airport",1,0) -> 0 | E5: =IF('2_Cleaned_Data'!D4="High Street",1,0) -> 0 | F5: =IF('2_Cleaned_Data'!D4="Mall",1,0) -> 0
A6: ='2_Cleaned_Data'!A5 -> STR-1001 | B6: ='2_Cleaned_Data'!B5 -> 45717 | C6: ='2_Cleaned_Data'!D5 -> Residential | D6: =IF('2_Cleaned_Data'!D5="Airport",1,0) -> 0 | E6: =IF('2_Cleaned_Data'!D5="High Street",1,0) -> 0 | F6: =IF('2_Cleaned_Data'!D5="Mall",1,0) -> 0
A7: ='2_Cleaned_Data'!A6 -> STR-1001 | B7: ='2_Cleaned_Data'!B6 -> 45748 | C7: ='2_Cleaned_Data'!D6 -> Residential | D7: =IF('2_Cleaned_Data'!D6="Airport",1,0) -> 0 | E7: =IF('2_Cleaned_Data'!D6="High Street",1,0) -> 0 | F7: =IF('2_Cleaned_Data'!D6="Mall",1,0) -> 0
A8: ='2_Cleaned_Data'!A7 -> STR-1002 | B8: ='2_Cleaned_Data'!B7 -> 45658 | C8: ='2_Cleaned_Data'!D7 -> High Street | D8: =IF('2_Cleaned_Data'!D7="Airport",1,0) -> 0 | E8: =IF('2_Cleaned_Data'!D7="High Street",1,0) -> 1 | F8: =IF('2_Cleaned_Data'!D7="Mall",1,0) -> 0
A9: ='2_Cleaned_Data'!A8 -> STR-1002 | B9: ='2_Cleaned_Data'!B8 -> 45689 | C9: ='2_Cleaned_Data'!D8 -> High Street | D9: =IF('2_Cleaned_Data'!D8="Airport",1,0) -> 0 | E9: =IF('2_Cleaned_Data'!D8="High Street",1,0) -> 1 | F9: =IF('2_Cleaned_Data'!D8="Mall",1,0) -> 0
A10: ='2_Cleaned_Data'!A9 -> STR-1002 | B10: ='2_Cleaned_Data'!B9 -> 45717 | C10: ='2_Cleaned_Data'!D9 -> High Street | D10: =IF('2_Cleaned_Data'!D9="Airport",1,0) -> 0 | E10: =IF('2_Cleaned_Data'!D9="High Street",1,0) -> 1 | F10: =IF('2_Cleaned_Data'!D9="Mall",1,0) -> 0
A11: ='2_Cleaned_Data'!A10 -> STR-1002 | B11: ='2_Cleaned_Data'!B10 -> 45748 | C11: ='2_Cleaned_Data'!D10 -> High Street | D11: =IF('2_Cleaned_Data'!D10="Airport",1,0) -> 0 | E11: =IF('2_Cleaned_Data'!D10="High Street",1,0) -> 1 | F11: =IF('2_Cleaned_Data'!D10="Mall",1,0) -> 0
A12: ='2_Cleaned_Data'!A11 -> STR-1003 | B12: ='2_Cleaned_Data'!B11 -> 45658 | C12: ='2_Cleaned_Data'!D11 -> Airport | D12: =IF('2_Cleaned_Data'!D11="Airport",1,0) -> 1 | E12: =IF('2_Cleaned_Data'!D11="High Street",1,0) -> 0 | F12: =IF('2_Cleaned_Data'!D11="Mall",1,0) -> 0
A13: ='2_Cleaned_Data'!A12 -> STR-1003 | B13: ='2_Cleaned_Data'!B12 -> 45689 | C13: ='2_Cleaned_Data'!D12 -> Airport | D13: =IF('2_Cleaned_Data'!D12="Airport",1,0) -> 1 | E13: =IF('2_Cleaned_Data'!D12="High Street",1,0) -> 0 | F13: =IF('2_Cleaned_Data'!D12="Mall",1,0) -> 0
A14: ='2_Cleaned_Data'!A13 -> STR-1003 | B14: ='2_Cleaned_Data'!B13 -> 45717 | C14: ='2_Cleaned_Data'!D13 -> Airport | D14: =IF('2_Cleaned_Data'!D13="Airport",1,0) -> 1 | E14: =IF('2_Cleaned_Data'!D13="High Street",1,0) -> 0 | F14: =IF('2_Cleaned_Data'!D13="Mall",1,0) -> 0
A15: ='2_Cleaned_Data'!A14 -> STR-1003 | B15: ='2_Cleaned_Data'!B14 -> 45748 | C15: ='2_Cleaned_Data'!D14 -> Airport | D15: =IF('2_Cleaned_Data'!D14="Airport",1,0) -> 1 | E15: =IF('2_Cleaned_Data'!D14="High Street",1,0) -> 0 | F15: =IF('2_Cleaned_Data'!D14="Mall",1,0) -> 0
... A309: ='2_Cleaned_Data'!A308 -> STR-1080 | B309: ='2_Cleaned_Data'!B308 -> 45748 | C309: ='2_Cleaned_Data'!D308 -> Residential | D309: =IF('2_Cleaned_Data'!D308="Airport",1,0) -> 0 | E309: =IF('2_Cleaned_Data'!D308="High Street",1,0) -> 0 | F309: =IF('2_Cleaned_Data'!D308="Mall",1,0) -> 0

Sheet 4_Simple_Regression
A1: Simple Regression Models — Formulas used: SLOPE, INTERCEPT, RSQ, INDEX(LINEST,...)
A3: Model 1: monthly_sales ~ marketing_spend
A4: Metric | B4: Value (formula) | C4: Interpretation
A5: Intercept ($) | B5: =INTERCEPT('2_Cleaned_Data'!M3:M308,'2_Cleaned_Data'!E3:E308) -> 567463.56 | C5: Predicted sales when marketing_spend = 0 (baseline)
A6: Coefficient | B6: =SLOPE('2_Cleaned_Data'!M3:M308,'2_Cleaned_Data'!E3:E308) -> 2.0519316 | C6: Change in monthly sales per unit increase in marketing_spend
A7: R-squared | B7: =RSQ('2_Cleaned_Data'!M3:M308,'2_Cleaned_Data'!E3:E308) -> 0.15742646 | C7: 15.74% of sales variation explained by this variable
A8: Observations | B8: =COUNT('2_Cleaned_Data'!M3:M308) -> 306 | C8: Number of data points used
A9: SE of Coefficient | B9: =INDEX(LINEST('2_Cleaned_Data'!M3:M308,'2_Cleaned_Data'!E3:E308,TRUE,TRUE),2,1) -> 0.27226457 | C9: Standard error of the slope coefficient
A10: df (residuals) | B10: =INDEX(LINEST('2_Cleaned_Data'!M3:M308,'2_Cleaned_Data'!E3:E308,TRUE,TRUE),4,2) -> 304 | C10: Degrees of freedom for residuals = n − 2
A11: T-statistic | B11: =B6/B9 -> 7.5365355
A12: P-value | B12: =_xlfn.T.DIST.2T(ABS(B11),B10) -> 5.5808923e-13 | C12: Two-tailed p-value; < 0.05 = statistically significant
A13: Regression Equation | B13: monthly_sales = 5,67,463.56 + 2.0519 x [marketing_spend] | C13: Every $1 increase in marketing spend leads to $2.05 increase in monthly_sales
A15: Model 2: monthly_sales ~ footfall
A16: Metric | B16: Value (formula) | C16: Interpretation
A17: Intercept ($) | B17: =INTERCEPT('2_Cleaned_Data'!M3:M308,'2_Cleaned_Data'!F3:F308) -> 447699.03 | C17: Predicted sales when footfall = 0 (baseline)
A18: Coefficient | B18: =SLOPE('2_Cleaned_Data'!M3:M308,'2_Cleaned_Data'!F3:F308) -> 35.641531 | C18: Change in monthly sales per unit increase in footfall
A19: R-squared | B19: =RSQ('2_Cleaned_Data'!M3:M308,'2_Cleaned_Data'!F3:F308) -> 0.73484317 | C19: 73% of sales variation explained by this variable
A20: Observations | B20: =COUNT('2_Cleaned_Data'!M3:M308) -> 306 | C20: Number of data points used
A21: SE of Coefficient | B21: =INDEX(LINEST('2_Cleaned_Data'!M3:M308,'2_Cleaned_Data'!F3:F308,TRUE,TRUE),2,1) -> 1.2279301 | C21: Standard error of the slope coefficient
A22: df (residuals) | B22: =INDEX(LINEST('2_Cleaned_Data'!M3:M308,'2_Cleaned_Data'!F3:F308,TRUE,TRUE),4,2) -> 304 | C22: Degrees of freedom for residuals = n − 2
A23: T-statistic | B23: =B18/B21 -> 29.025701
A24: P-value | B24: =_xlfn.T.DIST.2T(ABS(B23),B22) -> 1.2559351e-89 | C24: Two-tailed p-value; < 0.05 = statistically significant
A25: Regression Equation | B25: monthly_sales = 4,47,699.03 + 35.6415 x [footfall] | C25: Every 1000 increase in footfall leads to $35641 increase in monthly sales
A27: Model 3: monthly_sales ~ customer_rating
A28: Metric | B28: Value (formula) | C28: Interpretation
A29: Intercept ($) | B29: =INTERCEPT('2_Cleaned_Data'!M3:M308,'2_Cleaned_Data'!L3:L308) -> 703414.65 | C29: Predicted sales when customer_rating = 0 (baseline)
A30: Coefficient | B30: =SLOPE('2_Cleaned_Data'!M3:M308,'2_Cleaned_Data'!L3:L308) -> -5117.9739 | C30: Change in monthly sales per unit increase in customer_rating
A31: R-squared | B31: =RSQ('2_Cleaned_Data'!M3:M308,'2_Cleaned_Data'!L3:L308) -> 0.00069196261 | C31: Proportion of sales variation explained by this variable is insignificant
A32: Observations | B32: =COUNT('2_Cleaned_Data'!M3:M308) -> 306 | C32: Number of data points used
A33: SE of Coefficient | B33: =INDEX(LINEST('2_Cleaned_Data'!M3:M308,'2_Cleaned_Data'!L3:L308,TRUE,TRUE),2,1) -> 11155.002 | C33: Standard error of the slope coefficient
A34: df (residuals) | B34: =INDEX(LINEST('2_Cleaned_Data'!M3:M308,'2_Cleaned_Data'!L3:L308,TRUE,TRUE),4,2) -> 304 | C34: Degrees of freedom for residuals = n − 2
A35: T-statistic | B35: =B30/B33 -> -0.45880529
A36: P-value | B36: =_xlfn.T.DIST.2T(ABS(B35),B34) -> 0.64670185 | C36: Two-tailed p-value; > 0.05 = statistically NOT significant. Fail to reject Ho
A37: Regression Equation | B37: monthly_sales = 7,03,414.65 - 5117.9739 x [customer_rating] | C37: Equation using computed intercept and coefficient

Sheet 5_Multiple_Regression
A1: Multiple Regression Model (For output See row 313 onwards)
A3: monthly_sales (Y) | B3: marketing_spend (X1) | C3: footfall (X2) | D3: avg_discount_pct (X3) | E3: inventory_avail_pct (X4) | F3: store_Airport (X5) | G3: store_HighStreet (X6) | H3: store_Mall (X7)
A4: ='2_Cleaned_Data'!M3 -> 658832.62 | B4: ='2_Cleaned_Data'!E3 -> 70389.11 | C4: ='2_Cleaned_Data'!F3 -> 8302 | D4: ='2_Cleaned_Data'!G3 -> 0.042 | E4: ='2_Cleaned_Data'!I3 -> 75 | F4: =IF('2_Cleaned_Data'!D3="Airport",1,0) -> 0 | G4: =IF('2_Cleaned_Data'!D3="High Street",1,0) -> 0 | H4: =IF('2_Cleaned_Data'!D3="Mall",1,0) -> 0
A5: ='2_Cleaned_Data'!M4 -> 634436 | B5: ='2_Cleaned_Data'!E4 -> 43827.89 | C5: ='2_Cleaned_Data'!F4 -> 8487 | D5: ='2_Cleaned_Data'!G4 -> 0.168 | E5: ='2_Cleaned_Data'!I4 -> 84.4 | F5: =IF('2_Cleaned_Data'!D4="Airport",1,0) -> 0 | G5: =IF('2_Cleaned_Data'!D4="High Street",1,0) -> 0 | H5: =IF('2_Cleaned_Data'!D4="Mall",1,0) -> 0
A6: ='2_Cleaned_Data'!M5 -> 678722.06 | B6: ='2_Cleaned_Data'!E5 -> 59921.75 | C6: ='2_Cleaned_Data'!F5 -> 9113 | D6: ='2_Cleaned_Data'!G5 -> 0.133 | E6: ='2_Cleaned_Data'!I5 -> 88 | F6: =IF('2_Cleaned_Data'!D5="Airport",1,0) -> 0 | G6: =IF('2_Cleaned_Data'!D5="High Street",1,0) -> 0 | H6: =IF('2_Cleaned_Data'!D5="Mall",1,0) -> 0
A7: ='2_Cleaned_Data'!M6 -> 658920.3 | B7: ='2_Cleaned_Data'!E6 -> 56856.63 | C7: ='2_Cleaned_Data'!F6 -> 9431 | D7: ='2_Cleaned_Data'!G6 -> 0.142 | E7: ='2_Cleaned_Data'!I6 -> 86.9 | F7: =IF('2_Cleaned_Data'!D6="Airport",1,0) -> 0 | G7: =IF('2_Cleaned_Data'!D6="High Street",1,0) -> 0 | H7: =IF('2_Cleaned_Data'!D6="Mall",1,0) -> 0
A8: ='2_Cleaned_Data'!M7 -> 741341.44 | B8: ='2_Cleaned_Data'!E7 -> 48412.64 | C8: ='2_Cleaned_Data'!F7 -> 9545 | D8: ='2_Cleaned_Data'!G7 -> 0.231 | E8: ='2_Cleaned_Data'!I7 -> 97.6 | F8: =IF('2_Cleaned_Data'!D7="Airport",1,0) -> 0 | G8: =IF('2_Cleaned_Data'!D7="High Street",1,0) -> 1 | H8: =IF('2_Cleaned_Data'!D7="Mall",1,0) -> 0
A9: ='2_Cleaned_Data'!M8 -> 761835.34 | B9: ='2_Cleaned_Data'!E8 -> 64811.21 | C9: ='2_Cleaned_Data'!F8 -> 9792 | D9: ='2_Cleaned_Data'!G8 -> 0.112 | E9: ='2_Cleaned_Data'!I8 -> 84.2 | F9: =IF('2_Cleaned_Data'!D8="Airport",1,0) -> 0 | G9: =IF('2_Cleaned_Data'!D8="High Street",1,0) -> 1 | H9: =IF('2_Cleaned_Data'!D8="Mall",1,0) -> 0
A10: ='2_Cleaned_Data'!M9 -> 806615.54 | B10: ='2_Cleaned_Data'!E9 -> 46213.45 | C10: ='2_Cleaned_Data'!F9 -> 10616 | D10: ='2_Cleaned_Data'!G9 -> 0.122 | E10: ='2_Cleaned_Data'!I9 -> 85.2 | F10: =IF('2_Cleaned_Data'!D9="Airport",1,0) -> 0 | G10: =IF('2_Cleaned_Data'!D9="High Street",1,0) -> 1 | H10: =IF('2_Cleaned_Data'!D9="Mall",1,0) -> 0
A11: ='2_Cleaned_Data'!M10 -> 850164.26 | B11: ='2_Cleaned_Data'!E10 -> 68148.52 | C11: ='2_Cleaned_Data'!F10 -> 8567 | D11: ='2_Cleaned_Data'!G10 -> 0.127 | E11: ='2_Cleaned_Data'!I10 -> 95.6 | F11: =IF('2_Cleaned_Data'!D10="Airport",1,0) -> 0 | G11: =IF('2_Cleaned_Data'!D10="High Street",1,0) -> 1 | H11: =IF('2_Cleaned_Data'!D10="Mall",1,0) -> 0
A12: ='2_Cleaned_Data'!M11 -> 930581.7 | B12: ='2_Cleaned_Data'!E11 -> 71838.86 | C12: ='2_Cleaned_Data'!F11 -> 10979 | D12: ='2_Cleaned_Data'!G11 -> 0.215 | E12: ='2_Cleaned_Data'!I11 -> 88.6 | F12: =IF('2_Cleaned_Data'!D11="Airport",1,0) -> 1 | G12: =IF('2_Cleaned_Data'!D11="High Street",1,0) -> 0 | H12: =IF('2_Cleaned_Data'!D11="Mall",1,0) -> 0
A13: ='2_Cleaned_Data'!M12 -> 779010.94 | B13: ='2_Cleaned_Data'!E12 -> 68133.44 | C13: ='2_Cleaned_Data'!F12 -> 9459 | D13: ='2_Cleaned_Data'!G12 -> 0.22 | E13: ='2_Cleaned_Data'!I12 -> 85 | F13: =IF('2_Cleaned_Data'!D12="Airport",1,0) -> 1 | G13: =IF('2_Cleaned_Data'!D12="High Street",1,0) -> 0 | H13: =IF('2_Cleaned_Data'!D12="Mall",1,0) -> 0
A14: ='2_Cleaned_Data'!M13 -> 723060.76 | B14: ='2_Cleaned_Data'!E13 -> 34285.21 | C14: ='2_Cleaned_Data'!F13 -> 9172 | D14: ='2_Cleaned_Data'!G13 -> 0.213 | E14: ='2_Cleaned_Data'!I13 -> 88.3 | F14: =IF('2_Cleaned_Data'!D13="Airport",1,0) -> 1 | G14: =IF('2_Cleaned_Data'!D13="High Street",1,0) -> 0 | H14: =IF('2_Cleaned_Data'!D13="Mall",1,0) -> 0
A15: ='2_Cleaned_Data'!M14 -> 910791.94 | B15: ='2_Cleaned_Data'!E14 -> 67979.88 | C15: ='2_Cleaned_Data'!F14 -> 11230 | D15: ='2_Cleaned_Data'!G14 -> 0.002 | E15: ='2_Cleaned_Data'!I14 -> 85.3 | F15: =IF('2_Cleaned_Data'!D14="Airport",1,0) -> 1 | G15: =IF('2_Cleaned_Data'!D14="High Street",1,0) -> 0 | H15: =IF('2_Cleaned_Data'!D14="Mall",1,0) -> 0
... A309: ='2_Cleaned_Data'!M308 -> 559660.84 | B309: ='2_Cleaned_Data'!E308 -> 40553.11 | C309: ='2_Cleaned_Data'!F308 -> 5317 | D309: ='2_Cleaned_Data'!G308 -> 0.165 | E309: ='2_Cleaned_Data'!I308 -> 84.3 | F309: =IF('2_Cleaned_Data'!D308="Airport",1,0) -> 0 | G309: =IF('2_Cleaned_Data'!D308="High Street",1,0) -> 0 | H309: =IF('2_Cleaned_Data'!D308="Mall",1,0) -> 0
A313: SUMMARY OUTPUT
A315: Regression Statistics
A316: Multiple R | B316: 0.90328717
A317: R Square | B317: 0.81592771
A318: Adjusted R Square | B318: 0.81160386
A319: Standard Error | B319: 44675.837
A320: Observations | B320: 306
B323: Coefficients | C323: Standard Error | D323: t Stat | E323: P-value | F323: Lower 95% | G323: Upper 95% | H323: Lower 95.0% | I323: Upper 95.0% | J323: Significant? | K323: Business Interpretation
A324: Intercept | B324: 138186.46 | C324: 45400.87 | D324: 3.0436964 | E324: 0.0025452872 | F324: 48839.527 | G324: 227533.4 | H324: 48839.527 | I324: 227533.4 | J324: SIGNIFICANT | K324: Baseline monthly sales for Residential store (all numerics = 0)
A325: marketing_spend (X1) | B325: 1.16146 | C325: 0.13202042 | D325: 8.7975786 | E325: 1.1507235e-16 | F325: 0.90164954 | G325: 1.4212704 | H325: 0.90164954 | I325: 1.4212704 | J325: SIGNIFICANT | K325: Each additional $1 in marketing spend → change in monthly sales
A326: footfall (X2) | B326: 33.605032 | C326: 1.0643897 | D326: 31.572113 | E326: 4.5807918e-97 | F326: 31.510359 | G326: 35.699704 | H326: 31.510359 | I326: 35.699704 | J326: SIGNIFICANT | K326: Each additional customer visit → change in monthly sales
A327: avg_discount_pct (X3) | B327: -53521.13 | C327: 37902.163 | D327: -1.4120864 | E327: 0.15896789 | F327: -128110.94 | G327: 21068.678 | H327: -128110.94 | I327: 21068.678 | J327: NOT SIGNIFICANT | K327: Effect of a 1-unit increase in avg discount proportion (not significant)
A328: inventory_avail_pct (X4) | B328: 2824.4197 | C328: 487.5233 | D328: 5.7934045 | E328: 1.7521444e-08 | F328: 1864.995 | G328: 3783.8443 | H328: 1864.995 | I328: 3783.8443 | J328: SIGNIFICANT | K328: Each 1% improvement in inventory availability → change in monthly sales
A329: store_Airport (X5) | B329: 36186.237 | C329: 9639.8504 | D329: 3.7538173 | E329: 0.00020936177 | F329: 17215.431 | G329: 55157.044 | H329: 17215.431 | I329: 55157.044 | J329: SIGNIFICANT | K329: Airport store vs Residential — monthly sales premium
A330: store_HighStreet (X6) | B330: 14366.815 | C330: 6291.378 | D330: 2.283572 | E330: 0.023100306 | F330: 1985.6564 | G330: 26747.973 | H330: 1985.6564 | I330: 26747.973 | J330: SIGNIFICANT | K330: High Street store vs Residential — monthly sales premium
A331: store_Mall (X7) | B331: 25653.022 | C331: 6931.1085 | D331: 3.7011428 | E331: 0.00025560338 | F331: 12012.902 | G331: 39293.143 | H331: 12012.902 | I331: 39293.143 | J331: SIGNIFICANT | K331: Mall store vs Residential — monthly sales premium
A333: Equation (formula): | B333: monthly_sales = 1,38,186 + 1.1615 x mktg + 33.6050 x footfall + -53521.1295 x avg_disc + 2824.4197 x inv_avail + 36186.2374 x store_Airport + 14366.8146 x store_HStr + 25653.0224 x store_Mall

Sheet 6_Predictions_Residuals
A1: Predictions and Residuals — all computed by formula using Sheet 5 coefficients
A2: store_id | B2: month | C2: region | D2: store_type | E2: actual_sales ($) | F2: predicted_sales ($) | G2: residual ($) | H2: residual_%
A3: ='2_Cleaned_Data'!A3 -> STR-1001 | B3: ='2_Cleaned_Data'!B3 -> 45658 | C3: ='2_Cleaned_Data'!C3 -> East | D3: ='2_Cleaned_Data'!D3 -> Residential | E3: ='2_Cleaned_Data'!M3 -> 658832.62 | F3: ='5_Multiple_Regression'!$B$324+'5_Multiple_Regression'!$B$325*'2_Cleaned_Data'!E3+'5_Multiple_Regression'!$B$326*'2_Cleaned_Data'!F3+'5_Multiple_Regression'!$B$327*'2_Cleaned_Data'!G3+'5_Multiple_Regression'!$B$328*'2_Cleaned_Data'!I3+'5_Multiple_Regression'!$B$329*IF('2_Cleaned_Data'!D3="Airport",1,0)+'5_Multiple_Regression'!$B$330*IF('2_Cleaned_Data'!D3="High Street",1,0)+'5_Multiple_Regression'!$B$331*IF('2_Cleaned_Data'!D3="Mall",1,0) -> 708513.16 | G3: =E3-F3 -> -49680.538 | H3: =G3/E3*100 -> -7.5406918
A4: ='2_Cleaned_Data'!A4 -> STR-1001 | B4: ='2_Cleaned_Data'!B4 -> 45689 | C4: ='2_Cleaned_Data'!C4 -> East | D4: ='2_Cleaned_Data'!D4 -> Residential | E4: ='2_Cleaned_Data'!M4 -> 634436 | F4: ='5_Multiple_Regression'!$B$324+'5_Multiple_Regression'!$B$325*'2_Cleaned_Data'!E4+'5_Multiple_Regression'!$B$326*'2_Cleaned_Data'!F4+'5_Multiple_Regression'!$B$327*'2_Cleaned_Data'!G4+'5_Multiple_Regression'!$B$328*'2_Cleaned_Data'!I4+'5_Multiple_Regression'!$B$329*IF('2_Cleaned_Data'!D4="Airport",1,0)+'5_Multiple_Regression'!$B$330*IF('2_Cleaned_Data'!D4="High Street",1,0)+'5_Multiple_Regression'!$B$331*IF('2_Cleaned_Data'!D4="Mall",1,0) -> 703686.18 | G4: =E4-F4 -> -69250.177 | H4: =G4/E4*100 -> -10.915234
A5: ='2_Cleaned_Data'!A5 -> STR-1001 | B5: ='2_Cleaned_Data'!B5 -> 45717 | C5: ='2_Cleaned_Data'!C5 -> East | D5: ='2_Cleaned_Data'!D5 -> Residential | E5: ='2_Cleaned_Data'!M5 -> 678722.06 | F5: ='5_Multiple_Regression'!$B$324+'5_Multiple_Regression'!$B$325*'2_Cleaned_Data'!E5+'5_Multiple_Regression'!$B$326*'2_Cleaned_Data'!F5+'5_Multiple_Regression'!$B$327*'2_Cleaned_Data'!G5+'5_Multiple_Regression'!$B$328*'2_Cleaned_Data'!I5+'5_Multiple_Regression'!$B$329*IF('2_Cleaned_Data'!D5="Airport",1,0)+'5_Multiple_Regression'!$B$330*IF('2_Cleaned_Data'!D5="High Street",1,0)+'5_Multiple_Regression'!$B$331*IF('2_Cleaned_Data'!D5="Mall",1,0) -> 755456.45 | G5: =E5-F5 -> -76734.391 | H5: =G5/E5*100 -> -11.305716
A6: ='2_Cleaned_Data'!A6 -> STR-1001 | B6: ='2_Cleaned_Data'!B6 -> 45748 | C6: ='2_Cleaned_Data'!C6 -> East | D6: ='2_Cleaned_Data'!D6 -> Residential | E6: ='2_Cleaned_Data'!M6 -> 658920.3 | F6: ='5_Multiple_Regression'!$B$324+'5_Multiple_Regression'!$B$325*'2_Cleaned_Data'!E6+'5_Multiple_Regression'!$B$326*'2_Cleaned_Data'!F6+'5_Multiple_Regression'!$B$327*'2_Cleaned_Data'!G6+'5_Multiple_Regression'!$B$328*'2_Cleaned_Data'!I6+'5_Multiple_Regression'!$B$329*IF('2_Cleaned_Data'!D6="Airport",1,0)+'5_Multiple_Regression'!$B$330*IF('2_Cleaned_Data'!D6="High Street",1,0)+'5_Multiple_Regression'!$B$331*IF('2_Cleaned_Data'!D6="Mall",1,0) -> 758994.29 | G6: =E6-F6 -> -100073.99 | H6: =G6/E6*100 -> -15.187571
A7: ='2_Cleaned_Data'!A10 -> STR-1002 | B7: ='2_Cleaned_Data'!B10 -> 45748 | C7: ='2_Cleaned_Data'!C10 -> East | D7: ='2_Cleaned_Data'!D10 -> High Street | E7: ='2_Cleaned_Data'!M10 -> 850164.26 | F7: ='5_Multiple_Regression'!$B$324+'5_Multiple_Regression'!$B$325*'2_Cleaned_Data'!E10+'5_Multiple_Regression'!$B$326*'2_Cleaned_Data'!F10+'5_Multiple_Regression'!$B$327*'2_Cleaned_Data'!G10+'5_Multiple_Regression'!$B$328*'2_Cleaned_Data'!I10+'5_Multiple_Regression'!$B$329*IF('2_Cleaned_Data'!D10="Airport",1,0)+'5_Multiple_Regression'!$B$330*IF('2_Cleaned_Data'!D10="High Street",1,0)+'5_Multiple_Regression'!$B$331*IF('2_Cleaned_Data'!D10="Mall",1,0) -> 782816.7 | G7: =E7-F7 -> 67347.561 | H7: =G7/E7*100 -> 7.9217116
A8: ='2_Cleaned_Data'!A9 -> STR-1002 | B8: ='2_Cleaned_Data'!B9 -> 45717 | C8: ='2_Cleaned_Data'!C9 -> East | D8: ='2_Cleaned_Data'!D9 -> High Street | E8: ='2_Cleaned_Data'!M9 -> 806615.54 | F8: ='5_Multiple_Regression'!$B$324+'5_Multiple_Regression'!$B$325*'2_Cleaned_Data'!E9+'5_Multiple_Regression'!$B$326*'2_Cleaned_Data'!F9+'5_Multiple_Regression'!$B$327*'2_Cleaned_Data'!G9+'5_Multiple_Regression'!$B$328*'2_Cleaned_Data'!I9+'5_Multiple_Regression'!$B$329*IF('2_Cleaned_Data'!D9="Airport",1,0)+'5_Multiple_Regression'!$B$330*IF('2_Cleaned_Data'!D9="High Street",1,0)+'5_Multiple_Regression'!$B$331*IF('2_Cleaned_Data'!D9="Mall",1,0) -> 797090.34 | G8: =E8-F8 -> 9525.1959 | H8: =G8/E8*100 -> 1.1808843
A9: ='2_Cleaned_Data'!A8 -> STR-1002 | B9: ='2_Cleaned_Data'!B8 -> 45689 | C9: ='2_Cleaned_Data'!C8 -> East | D9: ='2_Cleaned_Data'!D8 -> High Street | E9: ='2_Cleaned_Data'!M8 -> 761835.34 | F9: ='5_Multiple_Regression'!$B$324+'5_Multiple_Regression'!$B$325*'2_Cleaned_Data'!E8+'5_Multiple_Regression'!$B$326*'2_Cleaned_Data'!F8+'5_Multiple_Regression'!$B$327*'2_Cleaned_Data'!G8+'5_Multiple_Regression'!$B$328*'2_Cleaned_Data'!I8+'5_Multiple_Regression'!$B$329*IF('2_Cleaned_Data'!D8="Airport",1,0)+'5_Multiple_Regression'!$B$330*IF('2_Cleaned_Data'!D8="High Street",1,0)+'5_Multiple_Regression'!$B$331*IF('2_Cleaned_Data'!D8="Mall",1,0) -> 788711.14 | G9: =E9-F9 -> -26875.804 | H9: =G9/E9*100 -> -3.5277707
A10: ='2_Cleaned_Data'!A7 -> STR-1002 | B10: ='2_Cleaned_Data'!B7 -> 45658 | C10: ='2_Cleaned_Data'!C7 -> East | D10: ='2_Cleaned_Data'!D7 -> High Street | E10: ='2_Cleaned_Data'!M7 -> 741341.44 | F10: ='5_Multiple_Regression'!$B$324+'5_Multiple_Regression'!$B$325*'2_Cleaned_Data'!E7+'5_Multiple_Regression'!$B$326*'2_Cleaned_Data'!F7+'5_Multiple_Regression'!$B$327*'2_Cleaned_Data'!G7+'5_Multiple_Regression'!$B$328*'2_Cleaned_Data'!I7+'5_Multiple_Regression'!$B$329*IF('2_Cleaned_Data'!D7="Airport",1,0)+'5_Multiple_Regression'!$B$330*IF('2_Cleaned_Data'!D7="High Street",1,0)+'5_Multiple_Regression'!$B$331*IF('2_Cleaned_Data'!D7="Mall",1,0) -> 792842.63 | G10: =E10-F10 -> -51501.187 | H10: =G10/E10*100 -> -6.9470266
A11: ='2_Cleaned_Data'!A11 -> STR-1003 | B11: ='2_Cleaned_Data'!B11 -> 45658 | C11: ='2_Cleaned_Data'!C11 -> North | D11: ='2_Cleaned_Data'!D11 -> Airport | E11: ='2_Cleaned_Data'!M11 -> 930581.7 | F11: ='5_Multiple_Regression'!$B$324+'5_Multiple_Regression'!$B$325*'2_Cleaned_Data'!E11+'5_Multiple_Regression'!$B$326*'2_Cleaned_Data'!F11+'5_Multiple_Regression'!$B$327*'2_Cleaned_Data'!G11+'5_Multiple_Regression'!$B$328*'2_Cleaned_Data'!I11+'5_Multiple_Regression'!$B$329*IF('2_Cleaned_Data'!D11="Airport",1,0)+'5_Multiple_Regression'!$B$330*IF('2_Cleaned_Data'!D11="High Street",1,0)+'5_Multiple_Regression'!$B$331*IF('2_Cleaned_Data'!D11="Mall",1,0) -> 865496.84 | G11: =E11-F11 -> 65084.857 | H11: =G11/E11*100 -> 6.9939971
A12: ='2_Cleaned_Data'!A14 -> STR-1003 | B12: ='2_Cleaned_Data'!B14 -> 45748 | C12: ='2_Cleaned_Data'!C14 -> North | D12: ='2_Cleaned_Data'!D14 -> Airport | E12: ='2_Cleaned_Data'!M14 -> 910791.94 | F12: ='5_Multiple_Regression'!$B$324+'5_Multiple_Regression'!$B$325*'2_Cleaned_Data'!E14+'5_Multiple_Regression'!$B$326*'2_Cleaned_Data'!F14+'5_Multiple_Regression'!$B$327*'2_Cleaned_Data'!G14+'5_Multiple_Regression'!$B$328*'2_Cleaned_Data'!I14+'5_Multiple_Regression'!$B$329*IF('2_Cleaned_Data'!D14="Airport",1,0)+'5_Multiple_Regression'!$B$330*IF('2_Cleaned_Data'!D14="High Street",1,0)+'5_Multiple_Regression'!$B$331*IF('2_Cleaned_Data'!D14="Mall",1,0) -> 871529.07 | G12: =E12-F12 -> 39262.869 | H12: =G12/E12*100 -> 4.3108494
A13: ='2_Cleaned_Data'!A12 -> STR-1003 | B13: ='2_Cleaned_Data'!B12 -> 45689 | C13: ='2_Cleaned_Data'!C12 -> North | D13: ='2_Cleaned_Data'!D12 -> Airport | E13: ='2_Cleaned_Data'!M12 -> 779010.94 | F13: ='5_Multiple_Regression'!$B$324+'5_Multiple_Regression'!$B$325*'2_Cleaned_Data'!E12+'5_Multiple_Regression'!$B$326*'2_Cleaned_Data'!F12+'5_Multiple_Regression'!$B$327*'2_Cleaned_Data'!G12+'5_Multiple_Regression'!$B$328*'2_Cleaned_Data'!I12+'5_Multiple_Regression'!$B$329*IF('2_Cleaned_Data'!D12="Airport",1,0)+'5_Multiple_Regression'!$B$330*IF('2_Cleaned_Data'!D12="High Street",1,0)+'5_Multiple_Regression'!$B$331*IF('2_Cleaned_Data'!D12="Mall",1,0) -> 799677.98 | G13: =E13-F13 -> -20667.042 | H13: =G13/E13*100 -> -2.6529848
A14: ='2_Cleaned_Data'!A13 -> STR-1003 | B14: ='2_Cleaned_Data'!B13 -> 45717 | C14: ='2_Cleaned_Data'!C13 -> North | D14: ='2_Cleaned_Data'!D13 -> Airport | E14: ='2_Cleaned_Data'!M13 -> 723060.76 | F14: ='5_Multiple_Regression'!$B$324+'5_Multiple_Regression'!$B$325*'2_Cleaned_Data'!E13+'5_Multiple_Regression'!$B$326*'2_Cleaned_Data'!F13+'5_Multiple_Regression'!$B$327*'2_Cleaned_Data'!G13+'5_Multiple_Regression'!$B$328*'2_Cleaned_Data'!I13+'5_Multiple_Regression'!$B$329*IF('2_Cleaned_Data'!D13="Airport",1,0)+'5_Multiple_Regression'!$B$330*IF('2_Cleaned_Data'!D13="High Street",1,0)+'5_Multiple_Regression'!$B$331*IF('2_Cleaned_Data'!D13="Mall",1,0) -> 760415.21 | G14: =E14-F14 -> -37354.446 | H14: =G14/E14*100 -> -5.1661559
A15: ='2_Cleaned_Data'!A15 -> STR-1004 | B15: ='2_Cleaned_Data'!B15 -> 45658 | C15: ='2_Cleaned_Data'!C15 -> East | D15: ='2_Cleaned_Data'!D15 -> Residential | E15: ='2_Cleaned_Data'!M15 -> 922168.6 | F15: ='5_Multiple_Regression'!$B$324+'5_Multiple_Regression'!$B$325*'2_Cleaned_Data'!E15+'5_Multiple_Regression'!$B$326*'2_Cleaned_Data'!F15+'5_Multiple_Regression'!$B$327*'2_Cleaned_Data'!G15+'5_Multiple_Regression'!$B$328*'2_Cleaned_Data'!I15+'5_Multiple_Regression'!$B$329*IF('2_Cleaned_Data'!D15="Airport",1,0)+'5_Multiple_Regression'!$B$330*IF('2_Cleaned_Data'!D15="High Street",1,0)+'5_Multiple_Regression'!$B$331*IF('2_Cleaned_Data'!D15="Mall",1,0) -> 875463.03 | G15: =E15-F15 -> 46705.573 | H15: =G15/E15*100 -> 5.0647542
A16: ='2_Cleaned_Data'!A18 -> STR-1004 | B16: ='2_Cleaned_Data'!B18 -> 45748 | C16: ='2_Cleaned_Data'!C18 -> East | D16: ='2_Cleaned_Data'!D18 -> Residential | E16: ='2_Cleaned_Data'!M18 -> 834017.02 | F16: ='5_Multiple_Regression'!$B$324+'5_Multiple_Regression'!$B$325*'2_Cleaned_Data'!E18+'5_Multiple_Regression'!$B$326*'2_Cleaned_Data'!F18+'5_Multiple_Regression'!$B$327*'2_Cleaned_Data'!G18+'5_Multiple_Regression'!$B$328*'2_Cleaned_Data'!I18+'5_Multiple_Regression'!$B$329*IF('2_Cleaned_Data'!D18="Airport",1,0)+'5_Multiple_Regression'!$B$330*IF('2_Cleaned_Data'!D18="High Street",1,0)+'5_Multiple_Regression'!$B$331*IF('2_Cleaned_Data'!D18="Mall",1,0) -> 809037.06 | G16: =E16-F16 -> 24979.965 | H16: =G16/E16*100 -> 2.9951385
A17: ='2_Cleaned_Data'!A17 -> STR-1004 | B17: ='2_Cleaned_Data'!B17 -> 45717 | C17: ='2_Cleaned_Data'!C17 -> East | D17: ='2_Cleaned_Data'!D17 -> Residential | E17: ='2_Cleaned_Data'!M17 -> 746501.09 | F17: ='5_Multiple_Regression'!$B$324+'5_Multiple_Regression'!$B$325*'2_Cleaned_Data'!E17+'5_Multiple_Regression'!$B$326*'2_Cleaned_Data'!F17+'5_Multiple_Regression'!$B$327*'2_Cleaned_Data'!G17+'5_Multiple_Regression'!$B$328*'2_Cleaned_Data'!I17+'5_Multiple_Regression'!$B$329*IF('2_Cleaned_Data'!D17="Airport",1,0)+'5_Multiple_Regression'!$B$330*IF('2_Cleaned_Data'!D17="High Street",1,0)+'5_Multiple_Regression'!$B$331*IF('2_Cleaned_Data'!D17="Mall",1,0) -> 745291.37 | G17: =E17-F17 -> 1209.7234 | H17: =G17/E17*100 -> 0.16205246
A18: ='2_Cleaned_Data'!A16 -> STR-1004 | B18: ='2_Cleaned_Data'!B16 -> 45689 | C18: ='2_Cleaned_Data'!C16 -> East | D18: ='2_Cleaned_Data'!D16 -> Residential | E18: ='2_Cleaned_Data'!M16 -> 726606.28 | F18: ='5_Multiple_Regression'!$B$324+'5_Multiple_Regression'!$B$325*'2_Cleaned_Data'!E16+'5_Multiple_Regression'!$B$326*'2_Cleaned_Data'!F16+'5_Multiple_Regression'!$B$327*'2_Cleaned_Data'!G16+'5_Multiple_Regression'!$B$328*'2_Cleaned_Data'!I16+'5_Multiple_Regression'!$B$329*IF('2_Cleaned_Data'!D16="Airport",1,0)+'5_Multiple_Regression'!$B$330*IF('2_Cleaned_Data'!D16="High Street",1,0)+'5_Multiple_Regression'!$B$331*IF('2_Cleaned_Data'!D16="Mall",1,0) -> 772743.45 | G18: =E18-F18 -> -46137.173 | H18: =G18/E18*100 -> -6.3496799
A19: ='2_Cleaned_Data'!A22 -> STR-1005 | B19: ='2_Cleaned_Data'!B22 -> 45748 | C19: ='2_Cleaned_Data'!C22 -> South | D19: ='2_Cleaned_Data'!D22 -> Residential | E19: ='2_Cleaned_Data'!M22 -> 591619.95 | F19: ='5_Multiple_Regression'!$B$324+'5_Multiple_Regression'!$B$325*'2_Cleaned_Data'!E22+'5_Multiple_Regression'!$B$326*'2_Cleaned_Data'!F22+'5_Multiple_Regression'!$B$327*'2_Cleaned_Data'!G22+'5_Multiple_Regression'!$B$328*'2_Cleaned_Data'!I22+'5_Multiple_Regression'!$B$329*IF('2_Cleaned_Data'!D22="Airport",1,0)+'5_Multiple_Regression'!$B$330*IF('2_Cleaned_Data'!D22="High Street",1,0)+'5_Multiple_Regression'!$B$331*IF('2_Cleaned_Data'!D22="Mall",1,0) -> 590748 | G19: =E19-F19 -> 871.94657 | H19: =G19/E19*100 -> 0.14738289
A20: ='2_Cleaned_Data'!A19 -> STR-1005 | B20: ='2_Cleaned_Data'!B19 -> 45658 | C20: ='2_Cleaned_Data'!C19 -> South | D20: ='2_Cleaned_Data'!D19 -> Residential | E20: ='2_Cleaned_Data'!M19 -> 666152.52 | F20: ='5_Multiple_Regression'!$B$324+'5_Multiple_Regression'!$B$325*'2_Cleaned_Data'!E19+'5_Multiple_Regression'!$B$326*'2_Cleaned_Data'!F19+'5_Multiple_Regression'!$B$327*'2_Cleaned_Data'!G19+'5_Multiple_Regression'!$B$328*'2_Cleaned_Data'!I19+'5_Multiple_Regression'!$B$329*IF('2_Cleaned_Data'!D19="Airport",1,0)+'5_Multiple_Regression'!$B$330*IF('2_Cleaned_Data'!D19="High Street",1,0)+'5_Multiple_Regression'!$B$331*IF('2_Cleaned_Data'!D19="Mall",1,0) -> 679455.32 | G20: =E20-F20 -> -13302.799 | H20: =G20/E20*100 -> -1.9969599
A21: ='2_Cleaned_Data'!A21 -> STR-1005 | B21: ='2_Cleaned_Data'!B21 -> 45717 | C21: ='2_Cleaned_Data'!C21 -> South | D21: ='2_Cleaned_Data'!D21 -> Residential | E21: ='2_Cleaned_Data'!M21 -> 666573.2 | F21: ='5_Multiple_Regression'!$B$324+'5_Multiple_Regression'!$B$325*'2_Cleaned_Data'!E21+'5_Multiple_Regression'!$B$326*'2_Cleaned_Data'!F21+'5_Multiple_Regression'!$B$327*'2_Cleaned_Data'!G21+'5_Multiple_Regression'!$B$328*'2_Cleaned_Data'!I21+'5_Multiple_Regression'!$B$329*IF('2_Cleaned_Data'!D21="Airport",1,0)+'5_Multiple_Regression'!$B$330*IF('2_Cleaned_Data'!D21="High Street",1,0)+'5_Multiple_Regression'!$B$331*IF('2_Cleaned_Data'!D21="Mall",1,0) -> 681628.21 | G21: =E21-F21 -> -15055.01 | H21: =G21/E21*100 -> -2.2585681
A22: ='2_Cleaned_Data'!A20 -> STR-1005 | B22: ='2_Cleaned_Data'!B20 -> 45689 | C22: ='2_Cleaned_Data'!C20 -> South | D22: ='2_Cleaned_Data'!D20 -> Residential | E22: ='2_Cleaned_Data'!M20 -> 573155.19 | F22: ='5_Multiple_Regression'!$B$324+'5_Multiple_Regression'!$B$325*'2_Cleaned_Data'!E20+'5_Multiple_Regression'!$B$326*'2_Cleaned_Data'!F20+'5_Multiple_Regression'!$B$327*'2_Cleaned_Data'!G20+'5_Multiple_Regression'!$B$328*'2_Cleaned_Data'!I20+'5_Multiple_Regression'!$B$329*IF('2_Cleaned_Data'!D20="Airport",1,0)+'5_Multiple_Regression'!$B$330*IF('2_Cleaned_Data'!D20="High Street",1,0)+'5_Multiple_Regression'!$B$331*IF('2_Cleaned_Data'!D20="Mall",1,0) -> 591157.94 | G22: =E22-F22 -> -18002.746 | H22: =G22/E22*100 -> -3.1409899
A23: ='2_Cleaned_Data'!A25 -> STR-1006 | B23: ='2_Cleaned_Data'!B25 -> 45717 | C23: ='2_Cleaned_Data'!C25 -> North | D23: ='2_Cleaned_Data'!D25 -> Residential | E23: ='2_Cleaned_Data'!M25 -> 555929.4 | F23: ='5_Multiple_Regression'!$B$324+'5_Multiple_Regression'!$B$325*'2_Cleaned_Data'!E25+'5_Multiple_Regression'!$B$326*'2_Cleaned_Data'!F25+'5_Multiple_Regression'!$B$327*'2_Cleaned_Data'!G25+'5_Multiple_Regression'!$B$328*'2_Cleaned_Data'!I25+'5_Multiple_Regression'!$B$329*IF('2_Cleaned_Data'!D25="Airport",1,0)+'5_Multiple_Regression'!$B$330*IF('2_Cleaned_Data'!D25="High Street",1,0)+'5_Multiple_Regression'!$B$331*IF('2_Cleaned_Data'!D25="Mall",1,0) -> 523364.68 | G23: =E23-F23 -> 32564.72 | H23: =G23/E23*100 -> 5.8577078
A24: ='2_Cleaned_Data'!A26 -> STR-1006 | B24: ='2_Cleaned_Data'!B26 -> 45748 | C24: ='2_Cleaned_Data'!C26 -> North | D24: ='2_Cleaned_Data'!D26 -> Residential | E24: ='2_Cleaned_Data'!M26 -> 565810.99 | F24: ='5_Multiple_Regression'!$B$324+'5_Multiple_Regression'!$B$325*'2_Cleaned_Data'!E26+'5_Multiple_Regression'!$B$326*'2_Cleaned_Data'!F26+'5_Multiple_Regression'!$B$327*'2_Cleaned_Data'!G26+'5_Multiple_Regression'!$B$328*'2_Cleaned_Data'!I26+'5_Multiple_Regression'!$B$329*IF('2_Cleaned_Data'!D26="Airport",1,0)+'5_Multiple_Regression'!$B$330*IF('2_Cleaned_Data'!D26="High Street",1,0)+'5_Multiple_Regression'!$B$331*IF('2_Cleaned_Data'!D26="Mall",1,0) -> 546645.6 | G24: =E24-F24 -> 19165.386 | H24: =G24/E24*100 -> 3.3872417
A25: ='2_Cleaned_Data'!A24 -> STR-1006 | B25: ='2_Cleaned_Data'!B24 -> 45689 | C25: ='2_Cleaned_Data'!C24 -> North | D25: ='2_Cleaned_Data'!D24 -> Residential | E25: ='2_Cleaned_Data'!M24 -> 491905.13 | F25: ='5_Multiple_Regression'!$B$324+'5_Multiple_Regression'!$B$325*'2_Cleaned_Data'!E24+'5_Multiple_Regression'!$B$326*'2_Cleaned_Data'!F24+'5_Multiple_Regression'!$B$327*'2_Cleaned_Data'!G24+'5_Multiple_Regression'!$B$328*'2_Cleaned_Data'!I24+'5_Multiple_Regression'!$B$329*IF('2_Cleaned_Data'!D24="Airport",1,0)+'5_Multiple_Regression'!$B$330*IF('2_Cleaned_Data'!D24="High Street",1,0)+'5_Multiple_Regression'!$B$331*IF('2_Cleaned_Data'!D24="Mall",1,0) -> 488934.99 | G25: =E25-F25 -> 2970.1352 | H25: =G25/E25*100 -> 0.60380244
A26: ='2_Cleaned_Data'!A23 -> STR-1006 | B26: ='2_Cleaned_Data'!B23 -> 45658 | C26: ='2_Cleaned_Data'!C23 -> North | D26: ='2_Cleaned_Data'!D23 -> Residential | E26: ='2_Cleaned_Data'!M23 -> 415721.82 | F26: ='5_Multiple_Regression'!$B$324+'5_Multiple_Regression'!$B$325*'2_Cleaned_Data'!E23+'5_Multiple_Regression'!$B$326*'2_Cleaned_Data'!F23+'5_Multiple_Regression'!$B$327*'2_Cleaned_Data'!G23+'5_Multiple_Regression'!$B$328*'2_Cleaned_Data'!I23+'5_Multiple_Regression'!$B$329*IF('2_Cleaned_Data'!D23="Airport",1,0)+'5_Multiple_Regression'!$B$330*IF('2_Cleaned_Data'!D23="High Street",1,0)+'5_Multiple_Regression'!$B$331*IF('2_Cleaned_Data'!D23="Mall",1,0) -> 495424.87 | G26: =E26-F26 -> -79703.054 | H26: =G26/E26*100 -> -19.172208
A27: ='2_Cleaned_Data'!A30 -> STR-1007 | B27: ='2_Cleaned_Data'!B30 -> 45748 | C27: ='2_Cleaned_Data'!C30 -> West | D27: ='2_Cleaned_Data'!D30 -> Mall | E27: ='2_Cleaned_Data'!M30 -> 701641.97 | F27: ='5_Multiple_Regression'!$B$324+'5_Multiple_Regression'!$B$325*'2_Cleaned_Data'!E30+'5_Multiple_Regression'!$B$326*'2_Cleaned_Data'!F30+'5_Multiple_Regression'!$B$327*'2_Cleaned_Data'!G30+'5_Multiple_Regression'!$B$328*'2_Cleaned_Data'!I30+'5_Multiple_Regression'!$B$329*IF('2_Cleaned_Data'!D30="Airport",1,0)+'5_Multiple_Regression'!$B$330*IF('2_Cleaned_Data'!D30="High Street",1,0)+'5_Multiple_Regression'!$B$331*IF('2_Cleaned_Data'!D30="Mall",1,0) -> 699081.67 | G27: =E27-F27 -> 2560.3038 | H27: =G27/E27*100 -> 0.36490175
A28: ='2_Cleaned_Data'!A29 -> STR-1007 | B28: ='2_Cleaned_Data'!B29 -> 45717 | C28: ='2_Cleaned_Data'!C29 -> West | D28: ='2_Cleaned_Data'!D29 -> Mall | E28: ='2_Cleaned_Data'!M29 -> 783672.82 | F28: ='5_Multiple_Regression'!$B$324+'5_Multiple_Regression'!$B$325*'2_Cleaned_Data'!E29+'5_Multiple_Regression'!$B$326*'2_Cleaned_Data'!F29+'5_Multiple_Regression'!$B$327*'2_Cleaned_Data'!G29+'5_Multiple_Regression'!$B$328*'2_Cleaned_Data'!I29+'5_Multiple_Regression'!$B$329*IF('2_Cleaned_Data'!D29="Airport",1,0)+'5_Multiple_Regression'!$B$330*IF('2_Cleaned_Data'!D29="High Street",1,0)+'5_Multiple_Regression'!$B$331*IF('2_Cleaned_Data'!D29="Mall",1,0) -> 791583.95 | G28: =E28-F28 -> -7911.1287 | H28: =G28/E28*100 -> -1.0094938
A29: ='2_Cleaned_Data'!A27 -> STR-1007 | B29: ='2_Cleaned_Data'!B27 -> 45658 | C29: ='2_Cleaned_Data'!C27 -> West | D29: ='2_Cleaned_Data'!D27 -> Mall | E29: ='2_Cleaned_Data'!M27 -> 811771.14 | F29: ='5_Multiple_Regression'!$B$324+'5_Multiple_Regression'!$B$325*'2_Cleaned_Data'!E27+'5_Multiple_Regression'!$B$326*'2_Cleaned_Data'!F27+'5_Multiple_Regression'!$B$327*'2_Cleaned_Data'!G27+'5_Multiple_Regression'!$B$328*'2_Cleaned_Data'!I27+'5_Multiple_Regression'!$B$329*IF('2_Cleaned_Data'!D27="Airport",1,0)+'5_Multiple_Regression'!$B$330*IF('2_Cleaned_Data'!D27="High Street",1,0)+'5_Multiple_Regression'!$B$331*IF('2_Cleaned_Data'!D27="Mall",1,0) -> 835507.02 | G29: =E29-F29 -> -23735.883 | H29: =G29/E29*100 -> -2.9239624
A30: ='2_Cleaned_Data'!A28 -> STR-1007 | B30: ='2_Cleaned_Data'!B28 -> 45689 | C30: ='2_Cleaned_Data'!C28 -> West | D30: ='2_Cleaned_Data'!D28 -> Mall | E30: ='2_Cleaned_Data'!M28 -> 800451.94 | F30: ='5_Multiple_Regression'!$B$324+'5_Multiple_Regression'!$B$325*'2_Cleaned_Data'!E28+'5_Multiple_Regression'!$B$326*'2_Cleaned_Data'!F28+'5_Multiple_Regression'!$B$327*'2_Cleaned_Data'!G28+'5_Multiple_Regression'!$B$328*'2_Cleaned_Data'!I28+'5_Multiple_Regression'!$B$329*IF('2_Cleaned_Data'!D28="Airport",1,0)+'5_Multiple_Regression'!$B$330*IF('2_Cleaned_Data'!D28="High Street",1,0)+'5_Multiple_Regression'!$B$331*IF('2_Cleaned_Data'!D28="Mall",1,0) -> 900057.35 | G30: =E30-F30 -> -99605.406 | H30: =G30/E30*100 -> -12.443646
A31: ='2_Cleaned_Data'!A32 -> STR-1008 | B31: ='2_Cleaned_Data'!B32 -> 45689 | C31: ='2_Cleaned_Data'!C32 -> East | D31: ='2_Cleaned_Data'!D32 -> Residential | E31: ='2_Cleaned_Data'!M32 -> 537383.79 | F31: ='5_Multiple_Regression'!$B$324+'5_Multiple_Regression'!$B$325*'2_Cleaned_Data'!E32+'5_Multiple_Regression'!$B$326*'2_Cleaned_Data'!F32+'5_Multiple_Regression'!$B$327*'2_Cleaned_Data'!G32+'5_Multiple_Regression'!$B$328*'2_Cleaned_Data'!I32+'5_Multiple_Regression'!$B$329*IF('2_Cleaned_Data'!D32="Airport",1,0)+'5_Multiple_Regression'!$B$330*IF('2_Cleaned_Data'!D32="High Street",1,0)+'5_Multiple_Regression'!$B$331*IF('2_Cleaned_Data'!D32="Mall",1,0) -> 527455.89 | G31: =E31-F31 -> 9927.9008 | H31: =G31/E31*100 -> 1.8474507
A32: ='2_Cleaned_Data'!A33 -> STR-1008 | B32: ='2_Cleaned_Data'!B33 -> 45717 | C32: ='2_Cleaned_Data'!C33 -> East | D32: ='2_Cleaned_Data'!D33 -> Residential | E32: ='2_Cleaned_Data'!M33 -> 500173.02 | F32: ='5_Multiple_Regression'!$B$324+'5_Multiple_Regression'!$B$325*'2_Cleaned_Data'!E33+'5_Multiple_Regression'!$B$326*'2_Cleaned_Data'!F33+'5_Multiple_Regression'!$B$327*'2_Cleaned_Data'!G33+'5_Multiple_Regression'!$B$328*'2_Cleaned_Data'!I33+'5_Multiple_Regression'!$B$329*IF('2_Cleaned_Data'!D33="Airport",1,0)+'5_Multiple_Regression'!$B$330*IF('2_Cleaned_Data'!D33="High Street",1,0)+'5_Multiple_Regression'!$B$331*IF('2_Cleaned_Data'!D33="Mall",1,0) -> 513595.73 | G32: =E32-F32 -> -13422.714 | H32: =G32/E32*100 -> -2.6836141
A33: ='2_Cleaned_Data'!A34 -> STR-1008 | B33: ='2_Cleaned_Data'!B34 -> 45748 | C33: ='2_Cleaned_Data'!C34 -> East | D33: ='2_Cleaned_Data'!D34 -> Residential | E33: ='2_Cleaned_Data'!M34 -> 427917.38 | F33: ='5_Multiple_Regression'!$B$324+'5_Multiple_Regression'!$B$325*'2_Cleaned_Data'!E34+'5_Multiple_Regression'!$B$326*'2_Cleaned_Data'!F34+'5_Multiple_Regression'!$B$327*'2_Cleaned_Data'!G34+'5_Multiple_Regression'!$B$328*'2_Cleaned_Data'!I34+'5_Multiple_Regression'!$B$329*IF('2_Cleaned_Data'!D34="Airport",1,0)+'5_Multiple_Regression'!$B$330*IF('2_Cleaned_Data'!D34="High Street",1,0)+'5_Multiple_Regression'!$B$331*IF('2_Cleaned_Data'!D34="Mall",1,0) -> 496829.62 | G33: =E33-F33 -> -68912.244 | H33: =G33/E33*100 -> -16.1041
A34: ='2_Cleaned_Data'!A31 -> STR-1008 | B34: ='2_Cleaned_Data'!B31 -> 45658 | C34: ='2_Cleaned_Data'!C31 -> East | D34: ='2_Cleaned_Data'!D31 -> Residential | E34: ='2_Cleaned_Data'!M31 -> 511844.41 | F34: ='5_Multiple_Regression'!$B$324+'5_Multiple_Regression'!$B$325*'2_Cleaned_Data'!E31+'5_Multiple_Regression'!$B$326*'2_Cleaned_Data'!F31+'5_Multiple_Regression'!$B$327*'2_Cleaned_Data'!G31+'5_Multiple_Regression'!$B$328*'2_Cleaned_Data'!I31+'5_Multiple_Regression'!$B$329*IF('2_Cleaned_Data'!D31="Airport",1,0)+'5_Multiple_Regression'!$B$330*IF('2_Cleaned_Data'!D31="High Street",1,0)+'5_Multiple_Regression'!$B$331*IF('2_Cleaned_Data'!D31="Mall",1,0) -> 585319.26 | G34: =E34-F34 -> -73474.846 | H34: =G34/E34*100 -> -14.354918
A35: ='2_Cleaned_Data'!A36 -> STR-1009 | B35: ='2_Cleaned_Data'!B36 -> 45717 | C35: ='2_Cleaned_Data'!C36 -> North | D35: ='2_Cleaned_Data'!D36 -> Residential | E35: ='2_Cleaned_Data'!M36 -> 798952.17 | F35: ='5_Multiple_Regression'!$B$324+'5_Multiple_Regression'!$B$325*'2_Cleaned_Data'!E36+'5_Multiple_Regression'!$B$326*'2_Cleaned_Data'!F36+'5_Multiple_Regression'!$B$327*'2_Cleaned_Data'!G36+'5_Multiple_Regression'!$B$328*'2_Cleaned_Data'!I36+'5_Multiple_Regression'!$B$329*IF('2_Cleaned_Data'!D36="Airport",1,0)+'5_Multiple_Regression'!$B$330*IF('2_Cleaned_Data'!D36="High Street",1,0)+'5_Multiple_Regression'!$B$331*IF('2_Cleaned_Data'!D36="Mall",1,0) -> 800190.88 | G35: =E35-F35 -> -1238.7077 | H35: =G35/E35*100 -> -0.15504154
A36: ='2_Cleaned_Data'!A37 -> STR-1009 | B36: ='2_Cleaned_Data'!B37 -> 45748 | C36: ='2_Cleaned_Data'!C37 -> North | D36: ='2_Cleaned_Data'!D37 -> Residential | E36: ='2_Cleaned_Data'!M37 -> 800979.78 | F36: ='5_Multiple_Regression'!$B$324+'5_Multiple_Regression'!$B$325*'2_Cleaned_Data'!E37+'5_Multiple_Regression'!$B$326*'2_Cleaned_Data'!F37+'5_Multiple_Regression'!$B$327*'2_Cleaned_Data'!G37+'5_Multiple_Regression'!$B$328*'2_Cleaned_Data'!I37+'5_Multiple_Regression'!$B$329*IF('2_Cleaned_Data'!D37="Airport",1,0)+'5_Multiple_Regression'!$B$330*IF('2_Cleaned_Data'!D37="High Street",1,0)+'5_Multiple_Regression'!$B$331*IF('2_Cleaned_Data'!D37="Mall",1,0) -> 816815.49 | G36: =E36-F36 -> -15835.705 | H36: =G36/E36*100 -> -1.9770418
A37: ='2_Cleaned_Data'!A35 -> STR-1009 | B37: ='2_Cleaned_Data'!B35 -> 45658 | C37: ='2_Cleaned_Data'!C35 -> North | D37: ='2_Cleaned_Data'!D35 -> Residential | E37: ='2_Cleaned_Data'!M35 -> 641865.03 | F37: ='5_Multiple_Regression'!$B$324+'5_Multiple_Regression'!$B$325*'2_Cleaned_Data'!E35+'5_Multiple_Regression'!$B$326*'2_Cleaned_Data'!F35+'5_Multiple_Regression'!$B$327*'2_Cleaned_Data'!G35+'5_Multiple_Regression'!$B$328*'2_Cleaned_Data'!I35+'5_Multiple_Regression'!$B$329*IF('2_Cleaned_Data'!D35="Airport",1,0)+'5_Multiple_Regression'!$B$330*IF('2_Cleaned_Data'!D35="High Street",1,0)+'5_Multiple_Regression'!$B$331*IF('2_Cleaned_Data'!D35="Mall",1,0) -> 743673.69 | G37: =E37-F37 -> -101808.66 | H37: =G37/E37*100 -> -15.861381
A38: ='2_Cleaned_Data'!A38 -> STR-1010 | B38: ='2_Cleaned_Data'!B38 -> 45658 | C38: ='2_Cleaned_Data'!C38 -> North | D38: ='2_Cleaned_Data'!D38 -> Mall | E38: ='2_Cleaned_Data'!M38 -> 820593.93 | F38: ='5_Multiple_Regression'!$B$324+'5_Multiple_Regression'!$B$325*'2_Cleaned_Data'!E38+'5_Multiple_Regression'!$B$326*'2_Cleaned_Data'!F38+'5_Multiple_Regression'!$B$327*'2_Cleaned_Data'!G38+'5_Multiple_Regression'!$B$328*'2_Cleaned_Data'!I38+'5_Multiple_Regression'!$B$329*IF('2_Cleaned_Data'!D38="Airport",1,0)+'5_Multiple_Regression'!$B$330*IF('2_Cleaned_Data'!D38="High Street",1,0)+'5_Multiple_Regression'!$B$331*IF('2_Cleaned_Data'!D38="Mall",1,0) -> 778049.03 | G38: =E38-F38 -> 42544.903 | H38: =G38/E38*100 -> 5.1846475
A39: ='2_Cleaned_Data'!A41 -> STR-1010 | B39: ='2_Cleaned_Data'!B41 -> 45748 | C39: ='2_Cleaned_Data'!C41 -> North | D39: ='2_Cleaned_Data'!D41 -> Mall | E39: ='2_Cleaned_Data'!M41 -> 828623.85 | F39: ='5_Multiple_Regression'!$B$324+'5_Multiple_Regression'!$B$325*'2_Cleaned_Data'!E41+'5_Multiple_Regression'!$B$326*'2_Cleaned_Data'!F41+'5_Multiple_Regression'!$B$327*'2_Cleaned_Data'!G41+'5_Multiple_Regression'!$B$328*'2_Cleaned_Data'!I41+'5_Multiple_Regression'!$B$329*IF('2_Cleaned_Data'!D41="Airport",1,0)+'5_Multiple_Regression'!$B$330*IF('2_Cleaned_Data'!D41="High Street",1,0)+'5_Multiple_Regression'!$B$331*IF('2_Cleaned_Data'!D41="Mall",1,0) -> 834980.79 | G39: =E39-F39 -> -6356.9431 | H39: =G39/E39*100 -> -0.76716874
A40: ='2_Cleaned_Data'!A40 -> STR-1010 | B40: ='2_Cleaned_Data'!B40 -> 45717 | C40: ='2_Cleaned_Data'!C40 -> North | D40: ='2_Cleaned_Data'!D40 -> Mall | E40: ='2_Cleaned_Data'!M40 -> 736633.4 | F40: ='5_Multiple_Regression'!$B$324+'5_Multiple_Regression'!$B$325*'2_Cleaned_Data'!E40+'5_Multiple_Regression'!$B$326*'2_Cleaned_Data'!F40+'5_Multiple_Regression'!$B$327*'2_Cleaned_Data'!G40+'5_Multiple_Regression'!$B$328*'2_Cleaned_Data'!I40+'5_Multiple_Regression'!$B$329*IF('2_Cleaned_Data'!D40="Airport",1,0)+'5_Multiple_Regression'!$B$330*IF('2_Cleaned_Data'!D40="High Street",1,0)+'5_Multiple_Regression'!$B$331*IF('2_Cleaned_Data'!D40="Mall",1,0) -> 749966.54 | G40: =E40-F40 -> -13333.138 | H40: =G40/E40*100 -> -1.8100099
...

Sheet 7_Model_Comparison
A1: Model Comparison — R-squared values and key metrics pulled from Sheets 4 and 5
A3: Model | B3: Dependent Variable | C3: Independent Variables | D3: R-squared | E3: Adj R-squared | F3: Key Significant Variables | G3: Business Usefulness | H3: Recommended?
A4: Simple Model 1 (marketing_spend) | B4: monthly_sales | C4: marketing_spend | D4: ='4_Simple_Regression'!$B$7 -> 0.15742646 | E4: n/a | F4: marketing_spend (p<0.001) | G4: Low-Moderate | H4: No
A5: Simple Model 2 (footfall) | B5: monthly_sales | C5: footfall | D5: ='4_Simple_Regression'!$B$19 -> 0.73484317 | E5: n/a | F5: footfall (p<0.001) | G5: High | H5: No
A6: Simple Model 3 (customer_rating) | B6: monthly_sales | C6: customer_rating | D6: ='4_Simple_Regression'!$B$31 -> 0.00069196261 | E6: n/a | F6: None (p=0.647, NS) | G6: None | H6: No
A7: Multiple Regression — FINAL | B7: monthly_sales | C7: marketing_spend, footfall, avg_discount_pct, inventory_availability_pct + 3 store dummy variables | D7: ='5_Multiple_Regression'!$B$317 -> 0.81592771 | E7: ='5_Multiple_Regression'!$B$318 -> 0.81160386 | F7: footfall***, marketing_spend***, inventory_avail***, store_Airport***, store_Mall***, store_HighStreet* | G7: High | H7: YES

Sheet 8_Residual_Plots
A1: Top 5 Positive Residuals
A2: store_id | B2: month | C2: region | D2: store_type | E2: actual_sales ($) | F2: predicted_sales ($) | G2: residual ($) | AA2: actual_sales ($) | AB2: predicted_sales ($) | AD2: predicted_sales ($) | AE2: residual ($) | AH2: monthly_sales | AI2: footfall
A3: ='2_Cleaned_Data'!A116 -> STR-1030 | B3: ='2_Cleaned_Data'!B116 -> 45689 | C3: ='2_Cleaned_Data'!C116 -> West | D3: ='2_Cleaned_Data'!D116 -> Residential | E3: ='2_Cleaned_Data'!M116 -> 820519.04 | F3: ='5_Multiple_Regression'!$B$324+'5_Multiple_Regression'!$B$325*'2_Cleaned_Data'!E116+'5_Multiple_Regression'!$B$326*'2_Cleaned_Data'!F116+'5_Multiple_Regression'!$B$327*'2_Cleaned_Data'!G116+'5_Multiple_Regression'!$B$328*'2_Cleaned_Data'!I116+'5_Multiple_Regression'!$B$329*IF('2_Cleaned_Data'!D116="Airport",1,0)+'5_Multiple_Regression'!$B$330*IF('2_Cleaned_Data'!D116="High Street",1,0)+'5_Multiple_Regression'!$B$331*IF('2_Cleaned_Data'!D116="Mall",1,0) -> 717684.66 | G3: =E3-F3 -> 102834.38 | AA3: 658832.62 | AB3: 708513.16 | AD3: 708513.16 | AE3: -49680.538 | AH3: 658832.62 | AI3: 8302
A4: ='2_Cleaned_Data'!A123 -> STR-1032 | B4: ='2_Cleaned_Data'!B123 -> 45658 | C4: ='2_Cleaned_Data'!C123 -> South | D4: ='2_Cleaned_Data'!D123 -> High Street | E4: ='2_Cleaned_Data'!M123 -> 914544.17 | F4: ='5_Multiple_Regression'!$B$324+'5_Multiple_Regression'!$B$325*'2_Cleaned_Data'!E123+'5_Multiple_Regression'!$B$326*'2_Cleaned_Data'!F123+'5_Multiple_Regression'!$B$327*'2_Cleaned_Data'!G123+'5_Multiple_Regression'!$B$328*'2_Cleaned_Data'!I123+'5_Multiple_Regression'!$B$329*IF('2_Cleaned_Data'!D123="Airport",1,0)+'5_Multiple_Regression'!$B$330*IF('2_Cleaned_Data'!D123="High Street",1,0)+'5_Multiple_Regression'!$B$331*IF('2_Cleaned_Data'!D123="Mall",1,0) -> 815637.11 | G4: =E4-F4 -> 98907.057 | AA4: 634436 | AB4: 703686.18 | AD4: 703686.18 | AE4: -69250.177 | AH4: 634436 | AI4: 8487
A5: ='2_Cleaned_Data'!A281 -> STR-1073 | B5: ='2_Cleaned_Data'!B281 -> 45717 | C5: ='2_Cleaned_Data'!C281 -> East | D5: ='2_Cleaned_Data'!D281 -> Residential | E5: ='2_Cleaned_Data'!M281 -> 813316.71 | F5: ='5_Multiple_Regression'!$B$324+'5_Multiple_Regression'!$B$325*'2_Cleaned_Data'!E281+'5_Multiple_Regression'!$B$326*'2_Cleaned_Data'!F281+'5_Multiple_Regression'!$B$327*'2_Cleaned_Data'!G281+'5_Multiple_Regression'!$B$328*'2_Cleaned_Data'!I281+'5_Multiple_Regression'!$B$329*IF('2_Cleaned_Data'!D281="Airport",1,0)+'5_Multiple_Regression'!$B$330*IF('2_Cleaned_Data'!D281="High Street",1,0)+'5_Multiple_Regression'!$B$331*IF('2_Cleaned_Data'!D281="Mall",1,0) -> 716285.37 | G5: =E5-F5 -> 97031.341 | AA5: 678722.06 | AB5: 755456.45 | AD5: 755456.45 | AE5: -76734.391 | AH5: 678722.06 | AI5: 9113
A6: ='2_Cleaned_Data'!A110 -> STR-1028 | B6: ='2_Cleaned_Data'!B110 -> 45748 | C6: ='2_Cleaned_Data'!C110 -> East | D6: ='2_Cleaned_Data'!D110 -> Mall | E6: ='2_Cleaned_Data'!M110 -> 713611.16 | F6: ='5_Multiple_Regression'!$B$324+'5_Multiple_Regression'!$B$325*'2_Cleaned_Data'!E110+'5_Multiple_Regression'!$B$326*'2_Cleaned_Data'!F110+'5_Multiple_Regression'!$B$327*'2_Cleaned_Data'!G110+'5_Multiple_Regression'!$B$328*'2_Cleaned_Data'!I110+'5_Multiple_Regression'!$B$329*IF('2_Cleaned_Data'!D110="Airport",1,0)+'5_Multiple_Regression'!$B$330*IF('2_Cleaned_Data'!D110="High Street",1,0)+'5_Multiple_Regression'!$B$331*IF('2_Cleaned_Data'!D110="Mall",1,0) -> 617601.63 | G6: =E6-F6 -> 96009.535 | AA6: 658920.3 | AB6: 758994.29 | AD6: 758994.29 | AE6: -100073.99 | AH6: 658920.3 | AI6: 9431
A7: ='2_Cleaned_Data'!A194 -> STR-1050 | B7: ='2_Cleaned_Data'!B194 -> 45748 | C7: ='2_Cleaned_Data'!C194 -> North | D7: ='2_Cleaned_Data'!D194 -> Residential | E7: ='2_Cleaned_Data'!M194 -> 735786.64 | F7: ='5_Multiple_Regression'!$B$324+'5_Multiple_Regression'!$B$325*'2_Cleaned_Data'!E194+'5_Multiple_Regression'!$B$326*'2_Cleaned_Data'!F194+'5_Multiple_Regression'!$B$327*'2_Cleaned_Data'!G194+'5_Multiple_Regression'!$B$328*'2_Cleaned_Data'!I194+'5_Multiple_Regression'!$B$329*IF('2_Cleaned_Data'!D194="Airport",1,0)+'5_Multiple_Regression'!$B$330*IF('2_Cleaned_Data'!D194="High Street",1,0)+'5_Multiple_Regression'!$B$331*IF('2_Cleaned_Data'!D194="Mall",1,0) -> 640920.91 | G7: =E7-F7 -> 94865.73 | AA7: 850164.26 | AB7: 782816.7 | AD7: 782816.7 | AE7: 67347.561 | AH7: 741341.44 | AI7: 9545
AA8: 806615.54 | AB8: 797090.34 | AD8: 797090.34 | AE8: 9525.1959 | AH8: 761835.34 | AI8: 9792
A9: Top 5 Negative Residuals | AA9: 761835.34 | AB9: 788711.14 | AD9: 788711.14 | AE9: -26875.804 | AH9: 806615.54 | AI9: 10616
A10: store_id | B10: month | C10: region | D10: store_type | E10: actual_sales ($) | F10: predicted_sales ($) | G10: residual ($) | AA10: 741341.44 | AB10: 792842.63 | AD10: 792842.63 | AE10: -51501.187 | AH10: 850164.26 | AI10: 8567
